Workbook

Sheet 0 Цели
A1: Цели набора (вводная владельца 17.08) и путь к 20 «Практикам»
A2: Цели ставит владелец — они выше прогноза, и это нормально: цель тянет, прогноз проверяет. Здесь — обратный расчёт: что должно стать правдой, чтобы цель была взята.
A4: Формулировка | B4: Минимум | C4: Максимум | D4: Примечание
A5: ЦЕЛЬ: продажи тарифа «Практик» до 04.11 | B5: 20 | C5: 60 | D5: Главная цель. Практик 1 659 € ранний / 1 869 € обычный.
A6: План на КАЖДЫЙ из тарифов | B6: 20 | C6: 60 | D6: Вводная владельца: мин/макс одинаковый на каждый тариф — это внутренние стретч-цели команды, не прогноз.
A7: Коммуникация НАРУЖУ (сайт, реклама, команда МИГ) | B7: 20 участий | C7: желательно 60 | D7: Общая цель по всем тарифам вместе. Внутренние потарифные цели наружу не транслируем.
A9: Обратный расчёт: что нужно для 20 «Практиков» к 04.11
A10: Шаг воронки | B10: Значение | D10: Норматив (совет)
A11: Оплат «Практик» | B11: 20 | D11: Цель
A12: Доля «Практика» в оплатах при Практик-центричных продажах | B12: 0.65 | D12: ДОПУЩЕНИЕ: интервью и лендинг продают ИМЕННО Практик (якорь), остальные тарифы — запасные позиции. Историческая доля — запрошена у Вали (лист 13, №3).
A13: Оплат всего (20 ÷ 0,65) | B13: =B11/B12 | D13: Формула ≈ 31 оплата — это ОПТИМИСТИЧНЫЙ сценарий таблицы (28) с небольшим превышением
A14: Интервью (÷ 0,60) | B14: =B13/0.6 | D14: интервью→оплата 60%
A15: Заявок (÷ 0,55 доходимость) | B15: =B14/0.55 | D15: с напоминаниями за 24ч/2ч
A16: Ответивших/дошедших (÷ 0,35) | B16: =B15/0.35 | D16: ответ→заявка 35%
A17: Тёплых контактов (÷ 0,25) | B17: =B16/0.25 | D17: средний % ответа по пулам
A18: Наши пулы сегодня (лист 3) | B18: ='3 План продаж ОП'!B11 | D18: ≈ 841 контакт против ~1 066 нужных → дефицит ~21%. Чем закрываем: промо вебинаров в Meta (регистрации ×1,5), полная выгрузка email-базы, «назови коллегу» у выпускников
A20: Что меняем в плане ради цели (Практик-центричность)
A21: 1. Интервью продаёт ТОЛЬКО Практик. Слушатель/Участник не предлагаем первыми — они существуют как «запасной выход» для тех, кто сам отказался. Якорение: разговор начинается с Практика и его супервизий.
A22: 2. Лендинг: Практик визуально выделен как выбор программы (без слова «популярный» — по правилам сайта: иерархией и полнотой описания).
A23: 3. Дедлайны считаем по Практику: «ранний Практик 1 659 € до 30.09 — выгода 210 €» — во всех письмах дедлайна.
A24: 4. Апгрейд-механика: правило «повышение тарифа до 4-й встречи» — отдельная волна продаж ПОСЛЕ старта 04.12 (Слушатели и Участники получают предложение апгрейда на 1-3 неделях программы). Продажи Практика не заканчиваются 04.11!
A25: 5. Выпускники: их статус (цена Участника, доступ Практика) уже продаёт ценность Практика — в письме прямо называем это «доступ уровня Практик».
A26: 6. Вебинары: в конце каждого — разбор именно механики супервизий и конференции случаев (ядро Практика), а не общий анонс.
A27: 7. Бюджет под цель: 20 Практиков ≈ 31 оплата = оптимистичный сценарий → нужен оптимистичный бюджет 4 000 € и ВСЕ условия листа 4 (обзвонщик, вторая ступень цены, добор до 04.12).
A29: ЧЕСТНАЯ РАМКА (правило «только правда») | D29: Цель 20 Практиков ≈ 31 оплата всего — на 55% выше реалистичного прогноза (20) и выше любого исторического потока (21 макс). Взять её можно только при одновременном выполнении ВСЕХ условий выше. Цель «60 Практиков» (≈92 оплаты) в это окно арифметически недостижима (пулы меньше в 3 раза) — это цель горизонта 2027, см. лист 4. Недельный контроль по Практику: 30.09 — 7, 25.10 — 13, 04.11 — 20.

Sheet Сводка
A1: Сложный случай — маркетинг и продажи до 04.12.2026
A2: Единая таблица Nova Leads, 17.08.2026. Голубые ячейки — допущения (правь их), чёрные — формулы. Источники — в примечаниях к ячейкам (наведи на уголок).
A4: Рамка (все — факты клиента)
A5: Параметр | B5: Значение | D5: Источник
A6: Старт потока | B6: 04.12.2026 | D6: Факт, Тина 17.08
A7: Дедлайн набора | B7: 04.11.2026 | D7: Факт, Тина 17.08
A8: Окно набора с сегодня | B8: 79 дней (17.08→04.11) | D8: Расчёт
A9: Цикл сделки | B9: 106 дней (3,5 мес) | D9: Факт, Валя
A10: ГЛАВНОЕ ОГРАНИЧЕНИЕ | B10: Окно КОРОЧЕ цикла на 27 дней → набор строится на тёплых пулах; холодный трафик работает на следующий поток | D10: Арифметика
A11: Цель | B11: минимум 20 оплат (потолок зала 60) | D11: Факт, Тина
A12: Исторические потоки | B12: 2023: 15 · 2024: 21 · 2025: 20 | D12: Факт, реестр участников
A13: Ранняя цена | B13: до 30.09.2026 | D13: Факт
A15: Три сценария одним взглядом (детали — листы 4, 8)
A16: Показатель | B16: Пессимистично | C16: Реалистично | D16: Оптимистично
A17: Оплат к 04.11 | B17: ='1 Юнит-экономика'!B23 | C17: ='1 Юнит-экономика'!C23 | D17: ='1 Юнит-экономика'!D23
A18: Выручка (ранние цены) | B18: ='1 Юнит-экономика'!B24 | C18: ='1 Юнит-экономика'!C24 | D18: ='1 Юнит-экономика'!D24
A19: Рекламный бюджет | B19: ='1 Юнит-экономика'!B26 | C19: ='1 Юнит-экономика'!C26 | D19: ='1 Юнит-экономика'!D26
A20: CAC (блендед) | B20: ='1 Юнит-экономика'!B27 | C20: ='1 Юнит-экономика'!C27 | D20: ='1 Юнит-экономика'!D27
A21: Бюджет / выручка | B21: ='1 Юнит-экономика'!B28 | C21: ='1 Юнит-экономика'!C28 | D21: ='1 Юнит-экономика'!D28
A23: Правило чтения: цифры со статусом ФАКТ взяты из данных клиента; ДОПУЩЕНИЕ — наша оценка на бенчмарках (источник в примечании); всё пересчитывается формулами при замене допущений.
A25: Почему у пессимиста бюджет МЕНЬШЕ: пессимистичный сценарий = плохой отклик, а при плохом отклике stop-loss останавливает траты (150 € без лида → стоп). Худший случай «потратили много — получили мало» посчитан отдельно: лист 1, раздел Г (стресс-тест).

Sheet 1 Юнит-экономика
A1: Юнит-экономика: лид и платящий клиент
A3: А. Юнит-экономика ЛИДА (что стоит один контакт и во что он превращается)
A4: Показатель | B4: Значение | E4: Источник / статус
A5: CPL лид-формы Meta (холод), факт 13.07–05.08.2026 | B5: 4.87 | E5: ФАКТ клиента (xlsx 07.08). ВНИМАНИЕ: кампания отключена из-за фрода, 90% лидов игнор. Эту цену НЕ закладываем в план.
A6: CPL холодного Meta на лендинг, план | B6: 20 | E6: ДОПУЩЕНИЕ 15–25 €. Бенчмарк образования: медиана ~21 € (WordStream/LocaliQ 2024, benchmarks.md R05). Вердикт совета: CPL 5 € — фродовый мусор, планировать по бенчмарку.
A7: CPL ретаргетинга (пиксель, вовлечённые IG/FB) | B7: 12 | E7: ДОПУЩЕНИЕ: тёплая аудитория в 1,5–2 раза дешевле холода (Meta best practices; наша бюджет-модель).
A8: CPL посева Telegram (профильные каналы психологов) | B8: 15 | E8: ДОПУЩЕНИЕ по протоколу R06 (TGStat-проверка каналов до оплаты).
A9: Цена регистрации на вебинар (промо в Meta) | B9: 4 | E9: ДОПУЩЕНИЕ 3–6 €: регистрация на бесплатное дешевле лида на платное; калибруем первым вебинаром.
A10: Цена КВАЛИФИЦИРОВАННОГО лида, факт 2026 | B10: 34.5 | E10: ФАКТ клиента: 25–44 € (11 квал из ~105). Это рабочая метрика вместо CPL.
A11: Конверсия лид → оплата С ПРОГРЕВОМ (вебинары) | B11: 0.072 | E11: ФАКТ 2025: 7,2% (10 студентов с рекламы из 138 лидов, 7 промо-вебинаров).
A12: Конверсия лид → оплата БЕЗ прогрева | B12: 0.01 | E12: ФАКТ 2026: ~1% (1 оплата из ~105 лидов лид-форм).
A13: Стоимость ОПЛАТЫ с прогревом (механика 2025) | B13: 72.3 | E13: ФАКТ 2025: 723 € ÷ 10 рекламных студентов.
A14: Стоимость ОПЛАТЫ холодным трафиком без прогрева | B14: 500 | E14: РАСЧЁТ: CPL 20 € ÷ конв. 4% (середина 1–7,2%) = 500 €. Внутри допустимого CAC 650–1350 € (R04), но в 7 раз дороже прогрева.
A15: ВЫВОД ПО ЛИДУ | B15: Лид без прогрева и быстрого касания сгорает: разница 7,2% против 1% — это ×7 к стоимости оплаты. Деньги решает не цена лида, а механика после лида.
A17: Б. Юнит-экономика ПЛАТЯЩЕГО КЛИЕНТА (три сценария)
A18: Показатель | B18: Пессимистично | C18: Реалистично | D18: Оптимистично | E18: Источник / статус
A19: Оплат на тарифе Слушатель (ранний 759 €) | B19: 3 | C19: 4 | D19: 5 | E19: ПЛАН (правится). Цены — ранние, факт из файла «Тарифы».
A20: Оплат на тарифе Участник (999 €) | B20: 4 | C20: 6 | D20: 8 | E20: ПЛАН (правится). Цены — ранние, факт из файла «Тарифы».
A21: Оплат на тарифе Практик (1 659 €) | B21: 4 | C21: 8 | D21: 12 | E21: ПЛАН (правится). Цены — ранние, факт из файла «Тарифы».
A22: Оплат на тарифе Профессионал (3 299 €) | B22: 1 | C22: 2 | D22: 3 | E22: ПЛАН (правится). Цены — ранние, факт из файла «Тарифы».
A23: ИТОГО оплат | B23: =SUM(B19:B22) | C23: =SUM(C19:C22) | D23: =SUM(D19:D22) | E23: Формула
A24: Выручка по ранним ценам | B24: =759*B19+999*B20+1659*B21+3299*B22 | C24: =759*C19+999*C20+1659*C21+3299*C22 | D24: =759*D19+999*D20+1659*D21+3299*D22 | E24: Формула. Консервативно: без пост-30.09 надбавки.
A25: Средний чек | B25: =IFERROR(B24/B23,0) | C25: =IFERROR(C24/C23,0) | D25: =IFERROR(D24/D23,0) | E25: Формула
A26: Рекламный бюджет сценария | B26: 1500 | C26: 2500 | D26: 4000 | E26: ПЛАН — детали на листе «8 Бюджет 3 сценария»
A27: CAC блендед (бюджет ÷ все оплаты) | B27: =IFERROR(B26/B23,0) | C27: =IFERROR(C26/C23,0) | D27: =IFERROR(D26/D23,0) | E27: Формула
A28: Бюджет / выручка | B28: =IFERROR(B26/B24,0) | C28: =IFERROR(C26/C24,0) | D28: =IFERROR(D26/D24,0) | E28: Формула. Ориентир отрасли: 10–20% выручки на маркетинг (Deloitte CMO Survey 2024 — в среднем ~10% выручки компании). Мы ниже за счёт тёплой базы.
A29: LTV-маржа студента (несколько программ за жизнь) | B29: 4100 | C29: 4100 | D29: 4100 | E29: ОЦЕНКА R04 (unit-экономика МИГ): допустимый CAC 650–1 350 €.
A30: LTV / CAC | B30: =IFERROR(B29/B26*B23,0) | C30: =IFERROR(C29/C26*C23,0) | D30: =IFERROR(D29/D26*D23,0) | E30: Формула. Норма ≥3
A32: ЧЕГО НЕ ХВАТАЕТ ДЛЯ ПОЛНОЙ ЮНИТ-ЭКОНОМИКИ | B32: Себестоимость программы (гонорары преподавателей/супервизоров, платформа) — без неё мы считаем выручку, а не прибыль. Запрошено у клиента (лист «Нужные данные», №1).
A34: В. CAC честно: тёплые и платные оплаты отдельно (правка совета аудиторов)
A35: Показатель | B35: Пессимистично | C35: Реалистично | D35: Оптимистично | E35: Источник / статус
A36: Из них оплат, пришедших С РЕКЛАМЫ (план) | B36: 2 | C36: 5 | D36: 9 | E36: ПЛАН; факт 2025 — 50/50 реклама/сарафан
A37: CAC рекламного клиента (бюджет ÷ оплаты с рекламы) | B37: =IFERROR(B26/B36,0) | C37: =IFERROR(C26/C36,0) | D37: =IFERROR(D26/D36,0) | E37: Формула
A38: Контроль: CAC рекламного ≤ допустимого (1 350 €)? | B38: =IF(IFERROR(B26/B36,0)<=1350,"да","НЕТ") | C38: =IF(IFERROR(C26/C36,0)<=1350,"да","НЕТ") | D38: =IF(IFERROR(D26/D36,0)<=1350,"да","НЕТ") | E38: Формула-контроль
A40: Г. СТРЕСС-ТЕСТ: «потратили много — получили мало» (вопрос владельца 17.08)
A41: Это НЕ сценарий плана, а проверка: что будет, если stop-loss не сработает и весь оптимистичный бюджет сгорит при пессимистичном отклике.
A42: Показатель | B42: Значение | E42: Что это означает
A43: Потрачено (весь оптимистичный бюджет) | B43: 4000 | E43: Ввод: худший случай трат
A44: Оплат получено (пессимистичный отклик) | B44: 12 | E44: Ввод: худший случай результата
A45: Из них с рекламы | B45: 2 | E45: Ввод: тёплые пулы дали остальное
...

Sheet 2 Маркетинг-план
A1: Маркетинг-план набора до 04.11 (стратегия)
A2: Главный принцип: окно 79 дней короче цикла сделки 106 дней → набор делают ТЁПЛЫЕ пулы и вебинары; холодный трафик — инвестиция в следующий поток.
A4: Этап | B4: Что делаем | C4: Зачем (на чём основано) | D4: Кто | E4: Срок
A5: 1. Фундамент | B5: Выгрузка пулов из AlfaCRM (95 лидов, отвалившиеся, email-база, выпускники) с размерами; UTM-разметка всех ссылок; доступ к Meta-кабинету; аудит фрода июльской кампании | C5: Без размеров пулов план — допущение. Без UTM не проверить, какой канал приводит оплаты (вердикт совета) | D5: Валя + Тина | E5: до 22.08
A6: 2. Тёплые пулы | B6: Реактивация 53 поимённых контактов (41 отвал + 12 недошедших) — WhatsApp с личного номера, 3 касания («старт перенесён на 04.12 + рассрочка от 69 €/мес»); письмо 56 выпускникам: «что починили» → статус выпускника → «назови 1 коллегу». Игнор-лиды июля СНЯТЫ (Молдова/Болгария, 0 из РФ) — только тест 10 контактов | C6: Самые дешёвые оплаты. Факт 2025: 50% студентов — не с рекламы. 34 из 41 отвала — март–май: им сейчас ровно цикл сделки, самое время вернуться | D6: Валя + менеджеры | E6: W01–W04
A7: 3. События | B7: ДОД 25.08 (нагнать до 90–140 рег.) → 3 живых вебинара (сент–окт, темы: телесность/сексуальность/клиника — факт: дают 100+ рег.) → автовебинар с октября | C7: Механика 2025: 7 промо-вебинаров дали конверсию 7,2% против 1% без прогрева — ×7 к эффективности | D7: Тина + ведущие | E7: W02–W10
A8: 4. Платный трафик | B8: Ретаргет Meta (пиксель + база) → посевы TG (каналы по протоколу R06) → Яндекс брендовый (защита от МИГиП/МГИ) → Meta холод с антифрод-фильтрами (лендинг, не лид-формы) | C8: Приоритет по вероятности оплаты на 1 €. Холод помечен «вклад в следующий поток» — его лиды в среднем не успевают пройти цикл 106 дней до 04.11 | D8: Тина | E8: W03–W11
A9: 5. Дедлайны | B9: Пуш ранней цены (3 письма: за 3 дня/за сутки/в день 30.09); вторая ступень цены 01.11 (запросить у клиента!); финальный дожим W11–W12 | C9: После 30.09 остаётся 5 недель без единого дедлайна — провал мотивации. Дедлайн — главный ускоритель цикла | D9: Тина + Валя | E9: 28.09–04.11
A10: 6. Хвост | B10: Waitlist для «не успел решиться» и «не подходит по датам» → добор до 04.12 (если разрешат) → передача тёплых остатков в следующий набор | C10: Лид с циклом 106 дней, пришедший в сентябре, дозревает в ноябре. Терять его — выбрасывать деньги | D10: Валя | E10: W12+
A11: 7. Позиционирование | B11: Кампания строится вокруг «как программа ложится в ваш год» (расписание, нагрузка в неделю, совместимость с практикой), НЕ вокруг цены и рассрочки | C11: Факт от Вали: «дорого» почти не возражают; реальные причины отказа — график, даты, зачёт часов. Продаём совместимость с жизнью | D11: все тексты | E11: постоянно

Sheet 3 План продаж ОП
A1: План продаж для отдела Вали (2 менеджера + РОП)
A2: Нормативы конверсий — по вердикту совета продаж: консервативные, ниже исторического максимума. План строится от цели назад.
A4: А. Воронка по пулам (реалистичный сценарий)
A5: Пул | B5: Контактов | C5: % ответа | D5: Заявок на интервью | E5: Оплат | F5: Комментарий
A6: Реактивация: отвал (поимённо, факт 17.08) | B6: 41 | C6: 0.3 | D6: 6 | E6: 3 | F6: ФАКТ: 34 из 41 — отвал марта–мая, им сейчас ровно цикл сделки. WhatsApp с личного номера, 3 касания: «изменились две вещи — старт 04.12 и рассрочка от 69 €/мес».
A7: Реактивация: недошедшие до старта | B7: 12 | C7: 0.35 | D7: 2 | E7: 1 | F7: ФАКТ поимённо, 11 из 12 в WhatsApp. Дошли до списков групп и не стартовали — новости о переносе и рассрочке бьют в их причину отказа.
A8: 56 выпускников трёх потоков | B8: 56 | C8: 0.45 | D8: 8 | E8: 4 | F8: Письмо №1 «что починили», №2 статус выпускника, №3 «назови коллегу». В контакт-листе 68: WhatsApp 47 / Telegram 20.
A9: Email-база «9 лекций» и рассылки | B9: 300 | C9: 0.1 | D9: 5 | E9: 2 | F9: РАЗМЕР — ДОПУЩЕНИЕ, единственный неизвестный пул (запрос у Вали до 20.08). Цепочка на вебинары + починить бесшовный доступ.
A10: ДОД 25.08 + 3 вебинара (регистранты) | B10: 340 | C10: 0.35 | D10: 30 | E10: 9 | F10: Доходимость до эфира 35% (с напоминаниями за 24 ч и 2 ч; без них 20%). Обработка заявок ≤1 часа.
A11: Игнор-лиды июля — СНЯТЫ (было 3 оплаты в плане) | B11: 96 | C11: 0 | D11: 0 | E11: 1 | F11: ФАКТ 17.08: Молдова 58% / Болгария 13%, НОЛЬ из России (Meta не показывает в РФ), 100% без ответа за 19 дней. Оставлен тест на 10 контактах, ожидание 0–1.
A12: ИТОГО (реалистичный) | B12: =SUM(B6:B11) | D12: =SUM(D6:D11) | E12: =SUM(E6:E11) | F12: Оплаты сходятся с реалистичным сценарием юнит-экономики (20)
A14: Б. Проверка нагрузки (вердикт совета: 20–30 касаний/день на менеджера)
A15: Показатель | B15: Значение | F15: Комментарий
A16: Контактов во всех пулах | B16: =SUM(B6:B11) | F16: Формула
A17: Касаний всего (×2,2 на контакт) | B17: =B16*2.2 | F17: Первое касание + напоминание + дожим
A18: Рабочих дней до 04.11 | B18: 56 | F18: 79 календарных дней ≈ 56 рабочих
A19: Касаний в день на отдел | B19: =B17/B18 | F19: Норматив совета: 20–30/день на менеджера = до 60 на двоих. Если выше — нужен обзвонщик (запрошен у клиента)
A21: В. Недельные цели по оплатам (кумулятивно)
A22: Контрольная точка | B22: Пессимистично | C22: Реалистично | D22: Оптимистично | F22: Что делает контрольная точка
A23: 30.09 — закрытие ранней цены | B23: 5 | C23: 8 | D23: 12 | F23: Первый большой дедлайн. Если факт < половины цели — пересбор плана, совет с владельцем.
A24: 25.10 — после вебинара №3 | B24: 9 | C24: 15 | D24: 22 | F24: Второй замер. Решение об интенсивности финального дожима.
A25: 04.11 — дедлайн набора | B25: 12 | C25: 20 | D25: 28 | F25: Минимум клиента: 20. Пессимист НЕ дотягивает — тогда добор до 04.12 (нужно решение клиента заранее!).
A27: Г. Правила работы (вердикт совета продаж)
A28: • SLA первого касания: ≤1 часа для горячих (вебинары, ДОД, сайт), ≤4 часов для реанимации. Это KPI, а не пожелание.
A29: • Квал-вопрос про даты и график ДО записи на интервью + расписание модулей в первом касании — главная причина отказов отсеивается на входе, слоты интервью не сгорают.
A30: • Политика зачёта часов МГИ — письменно (да/нет/частично). Запросить у методолога.
A31: • Не подходит по датам → лист ожидания следующего потока (это будущая выручка, не отказ).
A32: • Напоминания об интервью: за 24 ч и за 2 ч (голосовое/сообщение) — иначе доходимость падает с 70% к 50%.
A33: • После 3-го касания без ответа — пауза до следующего события (вебинар/дедлайн), не спамить.
A34: • KPI менеджера: оплаты + соблюдение SLA + доходимость до интервью. Мотивация: повышенный % за «Практик», бонус-спиф за 20-ю оплату потока (взятие рекорда).

Sheet 4 Набор 20-40-60
A1: Что стоит привлечь 20 / 40 / 60 оплативших
A2: Честно: 20 — план этого окна. 40 — только с добором до 04.12 и доп. бюджетом. 60 — не достижимо в это окно (расчёт ниже), планировать на поток-2027.
A4: Показатель | B4: Пессимистично | C4: Реалистично | D4: Оптимистично
A5: Оплат к 04.11 (из юнит-экономики) | B5: ='1 Юнит-экономика'!B23 | C5: ='1 Юнит-экономика'!C23 | D5: ='1 Юнит-экономика'!D23 | E5: Ссылка на лист 1
A7: Цель | B7: Откуда клиенты | C7: Бюджет | D7: Срок | E7: Условия успеха / честные оговорки
A8: 20 оплат (минимум клиента) | B8: Тёплые пулы 11 (95 лидов→3, выпускники→4, отвалившиеся→2, email→2) + вебинары и ДОД→9 | C8: 2 500 € | D8: к 04.11 | E8: Достижимо по нормативам совета. Ключевые условия: выгрузка пулов до 22.08, реанимация с W01, 3 вебинара проведены, SLA касания соблюдается. Риск: пулы меньше допущенных размеров.
A9: 40 оплат | B9: 20 базовых + 8–10 из waitlist и дозревших лидов вебинаров + 10–12 полухолодных (посевы, ретаргет, добор) | C9: 8 500–9 000 € суммарно | D9: к 04.12 (добор) | E9: НЕВОЗМОЖНО к 04.11 (окно короче цикла). Требует: (1) решение клиента о доборе до 04.12; (2) вторая ступень цены 01.11; (3) человек на обзвон; (4) доп. бюджет ~6 000 € на полухолодные по CAC ~500 €; (5) вебинары ×2 регистраций (промо в Meta).
A10: 60 оплат (потолок зала) | B10: Обратный расчёт от 60: при конверсиях совета нужно ~2 600 тёплых контактов — у нас ~840. База должна вырасти в 3 раза | C10: 15 000–25 000 € | D10: 6–9 месяцев прогрева | E10: В это окно НЕ достижимо: 60 = 3× исторический рекорд (21). Что должно стать правдой: база email 3 000+, автовебинар работает 6+ мес, 3–4 менеджера, бюджет 15–25 тыс. €, старт кампании за 2 цикла сделки (7 месяцев) до дедлайна. Реалистичная цель — поток осень-2027.

Sheet 5 Один клиент
A1: Стоимость привлечения ОДНОГО клиента — три сценария
A3: Сценарий | B3: CAC | C3: Механика | D3: Вероятность | E3: На чём основано
A4: Оптимистично | B4: 72–95 € | C4: Полное воспроизведение механики 2025: вебинары-прогрев + тёплая база + быстрая обработка | D4: Возможно при идеальном исполнении | E4: ФАКТ 2025: CAC 72,3 € (723 € ÷ 10 студентов). Совет: не гарантировано в сжатом окне 79 дней — 2025 набирался 7 месяцев.
A5: Реалистично | B5: 125–250 € | C5: Блендед: большинство оплат из тёплых пулов + платное усиление (ретаргет, посевы, промо вебинаров) | D5: Базовый план | E5: Расчёт: бюджет 2 500 € ÷ 20 оплат = 125 € блендед; чисто рекламный клиент 500 € (лист 1, раздел В). Вердикт совета аудиторов: 150–250 € — честный ориентир.
A6: Пессимистично | B6: 500–530 € | C6: Тёплые пулы не сработали (размеры меньше), тянем холодным трафиком без прогрева | D6: Guardrail для бюджета | E6: Расчёт: CPL 20 € ÷ конверсия 4% = 500 €. Внутри допустимого CAC 650–1 350 € (R04) — не убыточно, но в 7 раз дороже прогрева. Совет: закладывать как ориентир максимального бюджета, а не как экзотику.
A8: Правило: если фактический CAC к 30.09 выше 400 € — стоп платному холоду, весь бюджет в тёплые механики и вебинары.

Sheet 6 План-график рекламы
A1: План-график рекламы до старта 04.12 (какая реклама, где, сколько раз)
A2: Реалистичный сценарий, бюджет 2 500 €. Каждая строка — неделя. Даты дедлайнов — факты клиента.
A4: Неделя | B4: Даты | C4: Реклама и действия | D4: Каналы | E4: Бюджет | F4: Результат недели / контроль
A5: W01 | B5: 17–23.08 | C5: Выгрузка пулов; старт реанимации 95 лидов; письмо выпускникам; нагон на ДОД (email+посты); UTM-разметка | D5: База, email, соцсети МИГ | E5: 0 € | F5: Размеры пулов известны; 70+ регистраций ДОД
A6: W02 | B6: 24–30.08 | C6: ДОД 25.08; письма после ДОД (дошедшим/недошедшим — разные); запуск Яндекс брендовый; запрос доступа Meta | D6: ДОД, email, Яндекс | E6: 50 € | F6: 3–5 заявок на интервью; Яндекс: доля показов по бренду
A7: W03 | B7: 31.08–06.09 | C7: Аудит Meta-кабинета (фрод!); настройка пикселя и аудиторий; подготовка креативов теста (6 вариантов) | D7: Meta (подготовка) | E7: 0 € | F7: Аудит готов: причина фрода названа; креативы в работе
A8: W04 | B8: 07–13.09 | C8: ЗАПУСК ретаргетинга (пиксель+база) и ТЕСТА креативов (CTR-скрининг); сайт на домене | D8: Meta ретаргет + тест | E8: 300 € | F8: Тест идёт; CPL ретаргета ≤15 €
A9: W05 | B9: 14–20.09 | C9: Вебинар №1 (телесность/сексуальность); промо вебинара в Meta на тёплые; посевы: проверка каналов по R06 | D9: Вебинар, Meta, TGStat | E9: 150 € | F9: 100+ регистраций, 35+ живьём; список каналов посева готов
A10: W06 | B10: 21–27.09 | C10: CPL-раунд теста (2–3 победителя); первые посевы TG (2–3 канала); ретаргет на регистрантов вебинара | D10: Meta, посевы TG | E10: 400 € | F10: Победители теста известны; CPL посева ≤15 €
A11: W07 | B11: 28.09–04.10 | C11: ПУШ РАННЕЙ ЦЕНЫ: 3 письма (за 3 дня/за сутки/в день 30.09) + ретаргет-дедлайн на всех тёплых | D11: Email, Meta ретаргет | E11: 150 € | F11: Замер №1: 8 оплат (реалистично). Если <4 — пересбор плана
A12: W08 | B12: 05–11.10 | C12: Вебинар №2 (клиника: зависимость/РПП); автовебинар в TG-боте запущен на холод; Meta холод СТАРТ (лендинг, антифрод-фильтры) | D12: Вебинар, Meta холод | E12: 350 € | F12: 80–100 регистраций; холод помечен «следующий поток»
A13: W09 | B13: 12–18.10 | C13: Вторая волна посевов (3–4 канала по метрикам первых); обзвон отвалившихся (если есть человек) | D13: Посевы TG, обзвон | E13: 300 € | F13: +3–5 заявок; фактический CPL посевов сверен с планом
A14: W10 | B14: 19–25.10 | C14: Вебинар №3 (знакомство с ведущими); ретаргет на всех участников событий; Замер №2 | D14: Вебинар, Meta | E14: 200 € | F14: 15 оплат кумулятивно (реалистично)
A15: W11 | B15: 26.10–01.11 | C15: Финальная неделя: ретаргет-дедлайн «набор закрывается 04.11», личные сообщения всем незакрытым интервью | D15: Meta, email, личка | E15: 250 € | F15: Закрытие хвоста; каждая незакрытая заявка получила касание
... A17: W13–16 | B17: 05.11–04.12 | C17: Если добор разрешён: дожим waitlist + дозревших; вторая ступень цены 01.11→04.12; автовебинар работает; онбординг оплативших | D17: Email, автовебинар | E17: 350 € | F17: Добор до цели; старт 04.12 без волны негатива (онбординг!)
A18: ИТОГО | E18: 2 500 € | F18: Сходится с бюджетом реалистичного сценария (лист 8)

Sheet 7 Креативы
A1: Креативы: какие, где, на кого, какая цель
A2: Айдентика «Сложного случая»: тёмный фон, терракотовый акцент ≤5%, один крючок на кадр. Все тексты — через вычитку журналистом. ТЗ дизайнеру v2 уже выдано (5 сюжетов × 2 формата).
A4: Креатив / сюжет | B4: Формат | C4: Канал | D4: На кого нацелен | E4: Цель | F4: Как работает (механика убеждения)
A5: S1 «Сложные клиенты приходят раньше, чем к ним готов» | B5: 1080×1080 + 1080×1920 | C5: Meta холод + посевы | D5: Практикующие психологи 27–55, RU-speaking вне РФ | E5: Клик → лендинг | F5: Крючок-боль из текстов сайта: молодому терапевту сложное достаётся раньше опыта. Узнавание себя → клик.
A6: S2 «8 узких тем, за пределами базовой подготовки» | B6: оба формата | C6: Meta холод | D6: Психологи, ищущие специализацию | E6: Клик → лендинг | F6: Конкретика содержания (РПП, зависимости, горе, секс. травмы) — отстройка от «водянистых» курсов (боль из касдева n=170).
A7: S3 «Супервизия: 16 групп + конференция случаев» | B7: оба формата | C7: Meta ретаргет | D7: Видевшие лендинг, не оставившие заявку | E7: Заявка | F7: Дозакрытие возражения «нечёткие результаты»: показываем механику практики, не обещания.
A8: S4 «Ранний тариф до 30.09» | B8: оба формата | C8: Meta ретаргет + email | D8: Все тёплые: лиды, регистранты, посетители | E8: Оплата/заявка | F8: Дедлайн без манипуляции: честная дата, честная выгода (до 210 €). Работает в W06–W07.
A9: S5 Мастер-шаблон «крючок-тема» | B9: шаблон | C9: все каналы | D9: под замену крючка | E9: универсальный | F9: Быстрая генерация вариантов для тестов без нового дизайна.
A10: В1–В3 Афиши вебинаров (тема + ведущий + дата) | B10: 1080×1080 + сторис | C10: Meta тёплые, email, посевы | D10: Регистранты базы + холод на бесплатное | E10: Регистрация на вебинар | F10: Вебинар — главный конвертер (7,2% против 1%). Лицо ведущего = доверие. Темы — из доказанно сильных.
A11: Я1 Текстовые объявления Яндекс | B11: текст | C11: Яндекс Директ поиск | D11: Ищущие «МИГ гештальт», «сложный случай программа» | E11: Клик по бренду | F11: Защита бренда: чтобы искавшие НАС не ушли к МИГиП/МГИ. Точное соответствие, минус-слова.
A12: П1 Тексты посевов (3 варианта под тип канала) | B12: текст + 1 картинка | C12: Telegram-каналы психологов | D12: Подписчики профильных каналов | E12: Клик → лендинг/вебинар | F12: Нативный тон канала, без рекламного глянца. Маркировка erid. Вариант А: кейс-история; Б: программа; В: вебинар.
A13: Правило теста: в один момент тестируем ОДНУ переменную (крючок ИЛИ картинку). Победители — по CPL, не по CTR (лист 9).

Sheet 8 Бюджет 3 сценария
A1: Рекламный бюджет: сводная по трём сценариям
A2: Распределение — по вердикту совета: максимум в тёплые механики, посевы как тест, холод отдельной строкой на следующий поток.
A4: Канал | B4: Пессимистично | C4: Реалистично | D4: Оптимистично | E4: Почему столько (источник)
A5: Ретаргетинг Meta (пиксель + база + участники событий) | B5: 300 | C5: 500 | D5: 800 | E5: Совет: тёплое — приоритет №1 платных денег. CPL ~12 €, короткое плечо до оплаты.
A6: Промо вебинаров и ДОД (регистрации) | B6: 200 | C6: 300 | D6: 500 | E6: Вебинар — конвертер ×7 (факт 2025). Цена регистрации 3–6 €.
A7: Посевы Telegram (2–3 канала, потом ещё 3–4) | B7: 250 | C7: 450 | D7: 700 | E7: Совет: урезано с 800 — канал без факта конверсии для ЭТОГО продукта. Тест по протоколу R06.
A8: Холод: VK от ИП МИГа + Meta — вклад в СЛЕДУЮЩИЙ поток | B8: 100 | C8: 300 | D8: 600 | E8: Кабинет VK от ИП открыт 17.08 — ₽-ядро РФ. Лид холода в среднем не успевает пройти цикл до 04.11. Отдельная ROI-строка, не смешивать с целью «20 оплат».
A9: Яндекс Директ брендовый | B9: 50 | C9: 100 | D9: 150 | E9: Совет: низкочастотка, цель — доля показов по бренду (защита от МИГиП/МГИ), а не CPL.
A10: Тесты креативов (внутри Meta, выделено) | B10: 300 | C10: 650 | D10: 700 | E10: Расчёт на листе 9 (~656 €). Совет: 300–500 € на 8–12 вариантов не хватало — сокращён до 6 вариантов. Пессимист: 4 варианта.
A11: Автовебинар: трафик на бот | B11: 50 | C11: 50 | D11: 150 | E11: С октября, работает на хвост и следующий поток.
A12: Сервисы (TG-бот, email-платформа) | B12: 0 | C12: 0 | D12: 100 | E12: Стартуем на бесплатных тарифах; оптимист — платный тариф при росте базы.
A13: Резерв → в лидера по фактическому CAC | B13: 250 | C13: 150 | D13: 300 | E13: Размораживается после замера 30.09. Триггеры: CAC канала ≤ плана ×1,3.
A14: ИТОГО | B14: =SUM(B5:B13) | C14: =SUM(C5:C13) | D14: =SUM(D5:D13) | E14: Должно сходиться с бюджетом сценария на листе 1
A16: Stop-loss (переносится из бюджет-модели, работает для любого сценария)
A17: • Канал не тратит больше 150 € без лида и больше 400 € без заявки «хочу на программу» — стоп и разбор.
A18: • Meta: отключение объявления при CPL > 40 € (при ≥500 показов). Посевы: после 2 первых каналов сверка цены перехода.
A19: • Резерв не тратится до замера 30.09 — потом в канал-лидер по фактическому CAC (не по CPL!).
A20: • Еженедельная сверка факта с этой таблицей; деньги перекладываются по фактическому CAC.

Sheet 9 Тесты креативов
A1: Расчёт теста креативов (двухэтапный дизайн)
A2: Методология: этап 1 — CTR-скрининг (дёшево отсеять слабые), этап 2 — CPL-раунд только на победителях. Так малый бюджет даёт статистически осмысленный выбор.
A4: Этап 1. CTR-скрининг
A5: Параметр | B5: Значение | D5: Обоснование
A6: Вариантов креативов | B6: 6 | D6: Вердикт совета: 8–12 вариантов бюджет не тянет — 6 достаточно (3 крючка × 2 визуала).
A7: Показов на вариант | B7: 7700 | D7: Расчёт мощности теста пропорций (наша методичка, раздел 2)
A8: CPM (узкая психо-аудитория, RU-speaking вне РФ) | B8: 9 | D8: ДОПУЩЕНИЕ, калибруется в W04
A9: Бюджет этапа 1 | B9: =B6*B7/1000*B8 | D9: Формула: варианты × показы ÷ 1000 × CPM
A11: Этап 2. CPL-раунд (только победители)
A12: Параметр | B12: Значение | D12: Обоснование
A13: Победителей в раунде | B13: 2 | D13: Топ-2 по CTR при не худшем CPC
A14: Лидов на вариант для решения | B14: 10 | D14: Управленческий порог, не статистика (см. примечание)
A15: Плановый CPL раунда | B15: 12 | D15: Тёплые+ретаргет аудитории → ниже холодного CPL 20 €
A16: Бюджет этапа 2 | B16: =B13*B14*B15 | D16: Формула: победители × лиды × CPL
A17: ИТОГО бюджет теста | B17: =B9+B16 | D17: Заложено в строку «Тесты креативов» листа 8 (реалистично 550 €)
A19: Правила теста
A20: • Одна переменная за раз: сначала крючок (3 варианта при одном визуале), потом визуал.
A21: • Решение по этапу 1 — CTR и CPC; решение по этапу 2 — CPL; масштабирование — по CAC (цена ОПЛАТЫ, не лида!).
A22: • Аудитории этапов не пересекаются с боевым ретаргетом (исключения аудиторий), чтобы тест не крал дешёвые конверсии.
A23: • Антифрод: только плейсменты лент (без Audience Network), лендинг вместо лид-форм, гео/язык проверяются в разбивке.

Sheet 10 Расходы
A1: Все расходы: предполагаемые, случайные, непредвиденные
A2: Чек-лист совета аудиторов: что обычно забывают в таких планах. Рекламный бюджет — лист 8; здесь всё ОСТАЛЬНОЕ.
A4: Статья | B4: Оценка | C4: Комментарий / статус
A5: Комиссии рассрочек (Долями / Тинькофф) | B5: 3–8% от оплат в ₽ | C5: СТАВКА НЕИЗВЕСТНА — запрошена (типичный диапазон для продавца). Вычитать из выручки сразу, а не «потом».
A6: Комиссии международных платежей (EUR, конвертация) | B6: 1–4% + фикс | C6: Спред конвертации и SWIFT для оплат «картой любой страны». Уточнить у бухгалтерии клиента.
A7: Возвраты и отказы после оплаты | B7: 5–15% от оплат | C7: Типично для онлайн-образования (вердикт совета). Закладывать в пессимистичный кэшфлоу.
A8: Дизайнер креативов | B8: нужна цифра | C8: Нанят, стоимость работ не сообщена — запрошена. Объём: ТЗ v2 (10 макетов) + афиши вебинаров + шаблон.
A9: Вычитка журналистом | B9: внутренняя | C9: Процесс агентства (агент-редактор), денежных затрат нет.
A10: Сайт «Сложного случая» | B10: 0 € | C10: Статика по ТЗ, делает агентство/разработчик клиента. Если Tilda — от ~15 €/мес (проверить).
A11: Вебинарная платформа | B11: 0–50 €/мес | C11: Zoom у клиента есть; хватит ли тарифа на 100+ участников — проверить ДО вебинара №1.
A12: TG-бот (регистрации, автовебинар) | B12: 0–20 €/мес | C12: Конструкторы ботов: бесплатный тариф на старте.
A13: Модерация и простой кампаний | B13: риск времени | C13: Категория «образование/здоровье» у Meta проверяется строже: закладывать 1–2 дня на модерацию каждого запуска.
A14: Бухгалтерия трёх юрлиц, валютный контроль | B14: зона клиента | C14: ООО Черногория + ИП РФ + самозанятый: время и % конвертаций. Не наш бюджет, но влияет на скорость запусков.
A15: НЕПРЕДВИДЕННЫЕ (буфер) | B15: =15% | C15: Стандарт проектного управления: 10–20% медиабюджета. При базовом бюджете 2 500 € буфер = 375 € СВЕРХ бюджета — согласовать с клиентом заранее, чтобы не останавливать кампанию посреди теста.
A17: ГЛАВНАЯ ДЫРА ДАННЫХ | C17: Себестоимость программы (гонорары 11 преподавателей, супервизоров, платформа обучения) неизвестна агентству. Без неё вся таблица считает ВЫРУЧКУ, а не прибыль. Запрошено у клиента.

Sheet 11 Каналы продаж
A1: Каналы продаж: почему они, как тестируем, что работает
A3: Канал | B3: Почему он | C3: Как тестируем | D3: Что уже знаем (работает / нет)
A4: Переписка WhatsApp/Telegram (менеджеры) | B4: Политика клиента: звонков нет. Лиды сами оставили контакт | C4: A/B: 3 версии первого сообщения на партии 10–20 отвалившихся (даёт Валя), потом лучшая — на все пулы | D4: НЕ РАБОТАЕТ: «всё ли верно?» без ценности (факт: 90% игнор). ЖДЁМ: скрипт 3 касаний (подарок→событие→цена).
A5: Email-цепочки | B5: База есть, про программу ещё не писали — непуганый ресурс | C5: Замер open/click по каждому письму; 3 письма дедлайна 30.09 — отдельный замер | D5: Неизвестно: размер базы и её отклик. Бенчмарк образования: open ~28% (GetResponse 2024) — ориентир, не обещание.
A6: Интервью (Zoom, ведущие) | B6: Исторический конвертер 55–73% в оплату. Продаёт внимание, не скидка | C6: Фиксируем в Alfa: доходимость, длительность, исход. Напоминания за 24ч/2ч — тест влияния на доходимость | D6: РАБОТАЕТ (факт). Узкое место — пропускная способность ведущих: проверить, сколько слотов в неделю реально.
A7: Вебинары → заявка | B7: Механика 2025: конверсия 7,2% против 1% без прогрева | C7: Каждый вебинар: регистрации → живьём → заявки → оплаты. Сравниваем темы | D7: РАБОТАЕТ (факт 2025). НЕ работает: узкие авторские темы летом (Орлова 18.07 — 2 регистрации, факт).
A8: Обзвон (когда будет человек) | B8: Speed-to-lead: голос конвертит выше переписки | C8: Первые 50 звонков по 95 лидам против переписки — сравнение конверсии в диалог | D8: Неизвестно. Блокер: человека нет (запрошен у клиента, п. 11 «Что нужно от МИГа»).
A9: Рассрочка/помодульная оплата | B9: Снимает разовый платёж. НО: барьер клиентов — график, не деньги (факт от Вали) | C9: Тихая опция в оплате, НЕ строим кампанию вокруг неё. Замер: % выбравших рассрочку | D9: Помодульная РАБОТАЕТ (есть факт использования). Долями/Тинькофф — только карты РФ: международная часть не покрыта.
A10: Сарафан / рекомендации выпускников | B10: Факт 2025: 50% студентов не с рекламы | C10: «Назови 1 коллегу» в письме выпускникам; замер: сколько имён пришло | D10: РАБОТАЕТ пассивно. НЕ работало: промо «приведи и получи скидку» — ни одного использования (факт). Работает статус, не скидка.

Sheet 12 ТЗ на правки
A1: ТЗ на правки (по итогам этого расчёта и совета)
A2: Конкретные правки к сайту, процессу продаж и рекламной инфраструктуре. Дополняет «Открытые пункты» сайта и «Что нужно от МИГа».
A4: № | B4: Правка | C4: Кому | D4: Срок | E4: Зачем
A5: 1 | B5: Сайт: добавить вторую ступень цены 01.11 (между ранней 30.09 и стартом) | C5: учредитель → сайт | D5: 19.08 (созвон) | E5: После 30.09 — 5 недель набора без единого дедлайна. Дедлайн — главный ускоритель цикла.
A6: 2 | B6: Сайт: блок «Как программа ложится в ваш год» — расписание модулей, часы в неделю, совместимость с практикой | C6: методолог + сайт | D6: до 06.09 | E6: Главная причина отказов — график и даты (факт от Вали). Отвечаем на неё ДО интервью.
A7: 3 | B7: Сайт: честно решить противоречие «3–4 часа в неделю» против реальной пятницы Практика (модуль 10:00–14:00 + психоанализ 17:00–19:00) | C7: методолог | D7: до 06.09 | E7: Открытый пункт №11 сайта. Обещание, которое не сойдётся с реальностью, убьёт сарафан.
A8: 4 | B8: Сайт/процесс: письменная политика зачёта часов МГИ (да/нет/частично) | C8: методолог | D8: до 30.08 | E8: Третья причина отказов. Менеджеры отвечают одинаково, слоты интервью не сгорают.
A9: 5 | B9: Лид-магнит: бесшовный доступ к «9 лекциям» (ссылка сразу после заявки, без личного кабинета) | C9: разработчик | D9: до 06.09 | E9: Сейчас логин/пароль теряют людей на входе (пункт 7 «Что нужно от МИГа»).
A10: 6 | B10: Процесс: SLA первого касания ≤1 ч (горячие) / ≤4 ч (реанимация) — как KPI менеджеров в Alfa | C10: Валя | D10: с W01 | E10: Причина 90% игнора июля. Speed-to-lead ×21 (benchmarks.md).
A11: 7 | B11: Процесс: квал-вопрос про даты/график до записи на интервью + расписание в первом касании | C11: Валя | D11: с W01 | E11: Отсев главной причины отказа на входе воронки.
A12: 8 | B12: Процесс: waitlist для «не подходит по датам» и решение о доборе до 04.12 — заранее, не 03.11 | C12: учредитель | D12: 19.08 (созвон) | E12: Пессимистичный сценарий (12 оплат) не дотягивает до минимума 20 — добор становится планом Б.
A13: 9 | B13: Реклама: UTM-разметка всех ссылок + поля источника в Alfa | C13: Тина | D13: до 22.08 | E13: Без атрибуции невозможно проверить план по каналам (вердикт совета).
A14: 10 | B14: Реклама: антифрод-настройки Meta (без Audience Network, лендинг вместо лид-форм, гео/язык в разбивке) | C14: Тина | D14: до запуска W04 | E14: Июльский «фрод» — вероятно, настройки. Карантин-бюджет первой недели: 50 €/день максимум.
A15: 11 | B15: Онбординг оплативших: один личный кабинет, welcome-цепочка, честно про 2 супервизии | C15: администрация | D15: до 04.12 | E15: Прошлый поток начался с волны негатива — это бьёт по сарафану следующего набора (пункт 12 клиента).
A16: 12 | B16: Таблица клиента (план 17.08): заменить допущения воронки на консервативные нормативы совета (ответ 15–30%, доходимость 55–60%, интервью→оплата 60–65%) | C16: Тина | D16: сделано в этом файле | E16: Исходные 45%/72%/73% превышали исторический максимум — план не может стоять на рекорде.

Sheet 13 Нужные данные
A1: Какие данные нужны для точности (запрос клиенту)
A2: Пока этих данных нет, помеченные ДОПУЩЕНИЕМ числа — оценки. Каждый ответ делает таблицу точнее: заменяешь голубую ячейку — всё пересчитывается.
A4: № | B4: Данные | C4: У кого | D4: Что уточнит в таблице
A5: 1 | B5: Себестоимость программы: гонорары преподавателей/супервизоров, платформа | C5: учредитель | D5: Превратит расчёт выручки в расчёт ПРИБЫЛИ. Сейчас — главная дыра.
A6: 2 | B6: Выгрузка Alfa: размеры пулов (отвалившиеся, email-база, база «9 лекций») с контактами | C6: Валя, до 20.08 | D6: Лист 3: заменит допущения 50 и 300 фактами. От этого зависит, достижимы ли 20.
A7: 3 | B7: Разбивка прошлых потоков по тарифам (сколько брали Практик/Слушатель...) | C7: Валя | D7: Состав оплат в сценариях (лист 1) — сейчас это план, не факт. Совет: 9 Практиков — оптимизм.
A8: 4 | B8: История циклов сделки: какая доля сделок закрывалась быстрее 79 дней | C8: Валя (Alfa) | D8: Главный вопрос плана: успевают ли лиды сентября оплатить до 04.11. Сейчас — экспертная оценка.
A9: 5 | B9: Комиссии Долями/Тинькофф и международного эквайринга | C9: бухгалтерия | D9: Лист 10: реальные ставки вместо диапазонов 3–8%.
A10: 6 | B10: Стоимость дизайнера (ТЗ v2 + афиши + шаблон) | C10: Тина | D10: Лист 10: последняя неизвестная строка расходов агентства.
A11: 7 | B11: Доступ к Meta-кабинету + выгрузка июльской кампании | C11: учредитель, до 22.08 | D11: Аудит «фрода»: настройки или канал. От этого — конфигурация всего платного Meta.
A12: 8 | B12: Решение: добор до 04.12 разрешён? | C12: учредитель, 19.08 | D12: План Б пессимистичного сценария. Без решения заранее W13–16 пропадают.
A13: 9 | B13: Вторая ступень цены 01.11: да/нет | C13: учредитель, 19.08 | D13: Дедлайн-механика октября (лист 6, W11).
A14: 10 | B14: Человек на обзвон: будет/нет, когда | C14: учредитель, до 30.08 | D14: Каналы продаж: обзвон 95 лидов и отвалившихся. Без него — только переписка (конверсия ниже).
A15: 11 | B15: Имя/ИНН ИП МИГа | C15: Валя/учредитель | D15: Запуск Яндекс Директ от ИП + маркировка посевов (ОРД/erid).
A16: 12 | B16: Пропускная способность интервью: сколько слотов в неделю у ведущих | C16: методолог | D16: Узкое горло воронки в октябре (лист 3): 33 интервью должны физически поместиться в календарь.
A17: 13 | B17: Записи прошлых вебинаров + право использования | C17: администрация | D17: Автовебинар (W08+): лучшая запись становится машиной следующего потока.

Sheet 14 Источники
A1: Источники данных и исследований
A2: Правило агентства: у каждой цифры — источник и год. [A] — первичные данные клиента, [B] — отраслевые исследования, [C] — наши оценки, помеченные как допущения.
A4: Источник | B4: Что даёт | C4: Класс / год
A5: Данные МИГ: xlsx «продвижение 2025–2026» (получен 07.08) | B5: CAC 72,3 €, CPL 4,87 €, конверсии 7,2%/1%, цикл сделки, 138 лидов 2025, квал-лид 25–44 € | C5: [A] 2025–2026
A6: Реестр участников ППК 2023–2025 (получен 17.08) | B6: Потоки 15/21/20, состав аудитории (89–100% женщины) | C6: [A] 2023–2025
A7: План набора «Сложный случай» (файл клиента, 17.08) | B7: Рамка: даты, тарифы, пулы, вебинарные факты (сексология/телесность 100+, Орлова — 2), ответы Вали | C7: [A] 2026
A8: Файл «Сайт: структура и тексты» (17.08) | B8: Тарифы ранние/обычные, условия, скидки ДОД/ЯСНО, техтребования | C8: [A] 2026
A9: Переписка с Валей 08.08 (скриншоты) | B9: Кампания отключена (фрод), нет звонков, email-база не тронута, барьеры «график/даты/зачёт часов», интервью→оплата 55–73% | C9: [A] 2026
A10: Касдев «Цифра» n=170 (R13) | B10: Боли аудитории: «где брать клиентов» 83%, возражения «вода, нечёткие результаты» | C10: [A] 2026
A11: R04 Юнит-экономика МИГ (наше исследование) | B11: LTV-маржа ~4 100 €, допустимый CAC 650–1 350 € | C11: [C] 2026
A12: R05/benchmarks.md: WordStream / LocaliQ Facebook Ads Benchmarks | B12: CPL образования ~21 € медиана; CPC/CTR ориентиры. wordstream.com/blog/ws/2024/04/29/facebook-ads-benchmarks | C12: [B] 2024
A13: Meta Business Help: learning phase | B13: ~50 конверсий/неделю на ад-сет для выхода из обучения; статзначимость теста 50–100 конверсий. facebook.com/business/help/112167992830700 | C13: [B] тек.
A14: Lead response research (LeadResponseManagement.org; HBR «The Short Life of Online Sales Leads») | B14: Скорость первого касания: контакт в первые 5 минут кратно поднимает квалификацию (×21 против 30 мин); hbr.org/2011/03 | C14: [B] 2011/2021
A15: ON24 Webinar Benchmarks Report | B15: Доходимость вебинаров ~40% в среднем; с напоминаниями выше. on24.com/resources | C15: [B] 2024
... A21: Протокол R06 (проверка Telegram-каналов) | B21: TGStat-метрики канала до покупки посева | C21: [C] 2026
A23: Честная оговорка | B23: Класс [B] — ориентиры рынка, они НЕ заменяют наши факты: везде, где есть данные МИГ [A], план опирается на них. Все допущения [C] выделены голубым и пересчитываются заменой одной ячейки.
